#VRML_SIM R2019a utf8
WorldInfo {
}
Viewpoint {
  orientation -0.6993180062634123 0.709605604028985 0.08610582353375085 0.2443573336807484
  position 0.542882284426422 1.09270541237931 2.044097685959049
}
TexturedBackground {
}
TexturedBackgroundLight {
}
Floor {
}
Solid {
  translation 0 0.5 0
  children [
    Shape {
      appearance PBRAppearance {
        baseColor 0 0 0
      }
      geometry DEF G_CYL1 Cylinder {
        height 1
        radius 0.15
      }
    }
    HingeJoint {
      jointParameters HingeJointParameters {
        axis 0 1 0
        anchor 0 0.5 0
      }
      endPoint Solid {
        translation 0.2500011524123995 0.49999015348165554 0
        children [
          Shape {
            appearance PBRAppearance {
              baseColor 0.9862516212710766 0.007125963225757229 0.027435721370260166
            }
            geometry DEF G_REDBOX Box {
              size 0.5 0.01 0.1
            }
          }
          HingeJoint {
            jointParameters HingeJointParameters {
              axis 0 0 1
              anchor 0.25 0 0
            }
            endPoint Solid {
              translation 0.3 0 0
              rotation 0 0 1 0
              children [
                Shape {
                  appearance PBRAppearance {
                    baseColor 0.1313496604867628 0.9996795605401694 0.02362096589608606
                  }
                  geometry DEF G_GREENBOX Box {
                    size 0.1 0.01 0.1
                  }
                }
              ]
              boundingObject USE G_GREENBOX
              physics Physics {
              }
            }
          }
        ]
        boundingObject USE G_REDBOX
        physics Physics {
        }
      }
    }
  ]
}
