#VRML_SIM R2019a utf8
WorldInfo {
}
Viewpoint {
  orientation -0.9923600120354091 -0.12334250829185474 0.002869174333550254 0.2941750344965519
  position 0.3750179780157026 2.099307817953482 3.6931350983596136
}
TexturedBackground {
}
TexturedBackgroundLight {
}
Floor {
}
Solid {
  translation 0 0.5 0
  children [
    Shape {
      appearance PBRAppearance {
        baseColor 0 0 0
      }
      geometry DEF G_CYL1 Cylinder {
        height 1
        radius 0.15
      }
    }
    HingeJoint {
      jointParameters HingeJointParameters {
        axis 0 1 0
        anchor 0 0.5 0
      }
      endPoint Solid {
        translation 0.2500003924011246 0.5 0
        children [
          Shape {
            appearance PBRAppearance {
              baseColor 0.9862516212710766 0.007125963225757229 0.027435721370260166
            }
            geometry DEF G_REDBOX Box {
              size 0.5 0.01 0.1
            }
          }
        ]
        boundingObject USE G_REDBOX
        physics Physics {
        }
      }
    }
  ]
}
