#VRML_SIM R2019a utf8
WorldInfo {
}
Viewpoint {
  orientation -0.8932347291393088 0.4381045910242465 0.10097567025230955 0.43523987708170514
  position 1.0179286046171023 1.8993350057104417 1.8438545838154883
}
TexturedBackground {
}
TexturedBackgroundLight {
}
Floor {
}
Solid {
  translation 0 0.5 0
  children [
    Shape {
      appearance PBRAppearance {
        baseColor 0 0 0
      }
      geometry DEF G_CYL1 Cylinder {
        height 1
        radius 0.15
      }
    }
    HingeJoint {
      jointParameters HingeJointParameters {
        axis 0 1 0
        anchor 0 0.5 0
      }
      endPoint Solid {
        translation 0.24999898348478017 0.4999876825132309 0
        children [
          Shape {
            appearance PBRAppearance {
              baseColor 0.9862516212710766 0.007125963225757229 0.027435721370260166
            }
            geometry DEF G_REDBOX Box {
              size 0.5 0.01 0.1
            }
          }
          HingeJoint {
            jointParameters HingeJointParameters {
              axis 0 0 1
              anchor 0.25 0 0
              staticFriction 0.01
            }
            endPoint Solid {
              translation 0.3 0 0
              rotation 0 0 1 0
              children [
                Shape {
                  appearance PBRAppearance {
                    baseColor 0.1313496604867628 0.9996795605401694 0.02362096589608606
                  }
                  geometry DEF G_GREENBOX Box {
                    size 0.1 0.01 0.1
                  }
                }
                HingeJoint {
                  jointParameters HingeJointParameters {
                    anchor 0.05 0 0
                  }
                  endPoint Solid {
                    translation 0.125 0 0
                    rotation 1 0 0 0
                    children [
                      Shape {
                        appearance PBRAppearance {
                          baseColor 0.00010681315327687495 0.0017547875181200886 0.9982146944380865
                        }
                        geometry DEF G_BLUEBOX Box {
                          size 0.15 0.01 0.1
                        }
                      }
                    ]
                    boundingObject USE G_BLUEBOX
                    physics Physics {
                    }
                  }
                }
              ]
              boundingObject USE G_GREENBOX
              physics Physics {
              }
            }
          }
        ]
        boundingObject USE G_REDBOX
        physics Physics {
        }
      }
    }
  ]
}
